Workbook

Sheet Sheet1
P2: Factory
B3: Date | C3: Article | D3: Quantity | E3: Amount/pice | F3: KAAJ/Button | G3: Amount | H3: Elect | I3: MIS | J3: Rent | K3: Transpotaion | L3: Maintanace | M3: Helper | N3: Supp | O3: Total | P3: Amount/pice | Q3: Total | R3: Profit
B4: 43044 | C4: 1 | D4: 1000 | E4: 47 | F4: 3 | G4: =D4*(E4+F4) -> 50000 | H4: 266.66667 | I4: 333.33333 | J4: 700 | L4: 233.33333 | M4: 600 | N4: 1166 | O4: =G4+H4+I4+J4+L4+M4+N4 -> 53299.333 | P4: 80 | Q4: =P4*D4 -> 80000 | R4: =Q4-O4 -> 26700.667
B5: 43045 | D5: 1000 | E5: 47 | F5: 3 | G5: =D5*(E5+F5) -> 50000 | H5: 266.66667 | I5: 333.33333 | J5: 700 | L5: 233.33333 | M5: 600 | N5: 1166 | O5: =G5+H5+I5+J5+L5+M5+N5 -> 53299.333 | P5: 80 | Q5: =P5*D5 -> 80000 | R5: =Q5-O5 -> 26700.667
B6: 43046 | D6: 1000 | E6: 47 | F6: 3 | G6: =D6*(E6+F6) -> 50000 | H6: 266.66667 | I6: 333.33333 | J6: 700 | L6: 233.33333 | M6: 600 | N6: 1166 | O6: =G6+H6+I6+J6+L6+M6+N6 -> 53299.333 | P6: 80 | Q6: =P6*D6 -> 80000 | R6: =Q6-O6 -> 26700.667
B7: 43047 | D7: 1000 | E7: 47 | F7: 3 | G7: =D7*(E7+F7) -> 50000 | H7: 266.66667 | I7: 333.33333 | J7: 700 | L7: 233.33333 | M7: 600 | N7: 1166 | O7: =G7+H7+I7+J7+L7+M7+N7 -> 53299.333 | P7: 80 | Q7: =P7*D7 -> 80000 | R7: =Q7-O7 -> 26700.667
B8: 43048 | D8: 1000 | E8: 47 | F8: 3 | G8: =D8*(E8+F8) -> 50000 | H8: 266.66667 | I8: 333.33333 | J8: 700 | L8: 233.33333 | M8: 600 | N8: 1166 | O8: =G8+H8+I8+J8+L8+M8+N8 -> 53299.333 | P8: 80 | Q8: =P8*D8 -> 80000 | R8: =Q8-O8 -> 26700.667
B9: 43049 | D9: 1000 | E9: 47 | F9: 3 | G9: =D9*(E9+F9) -> 50000 | H9: 266.66667 | I9: 333.33333 | J9: 700 | L9: 233.33333 | M9: 600 | N9: 1166 | O9: =G9+H9+I9+J9+L9+M9+N9 -> 53299.333 | P9: 80 | Q9: =P9*D9 -> 80000 | R9: =Q9-O9 -> 26700.667
B10: 43050 | D10: 1000 | E10: 47 | F10: 3 | G10: =D10*(E10+F10) -> 50000 | H10: 266.66667 | I10: 333.33333 | J10: 700 | L10: 233.33333 | M10: 600 | N10: 1166 | O10: =G10+H10+I10+J10+L10+M10+N10 -> 53299.333 | P10: 80 | Q10: =P10*D10 -> 80000 | R10: =Q10-O10 -> 26700.667
B11: 43051 | D11: 1000 | E11: 47 | F11: 3 | G11: =D11*(E11+F11) -> 50000 | H11: 266.66667 | I11: 333.33333 | J11: 700 | L11: 233.33 | M11: 600 | N11: 1166
B12: 43052 | D12: 1000 | E12: 47 | F12: 3 | G12: =D12*(E12+F12) -> 50000 | H12: 266.66667 | I12: 333.33333 | J12: 700 | L12: 233.33 | M12: 600 | N12: 1166 | O12: =#REF!*5.2 -> #REF!
B13: 43053 | D13: 1000 | E13: 47 | F13: 3 | G13: =D13*(E13+F13) -> 50000 | H13: 266.66667 | I13: 333.33333 | J13: 700 | L13: 233.33 | M13: 600 | N13: 1166
B14: 43054 | D14: 1000 | E14: 47 | F14: 3 | G14: =D14*(E14+F14) -> 50000 | H14: 266.66667 | I14: 333.33333 | J14: 700 | L14: 233.33 | M14: 600 | N14: 1166
B15: 43055 | D15: 1000 | E15: 47 | F15: 3 | G15: =D15*(E15+F15) -> 50000 | H15: 266.66667 | I15: 333.33333 | J15: 700 | L15: 233.33 | M15: 600 | N15: 1166
B16: 43056 | D16: 1000 | E16: 47 | F16: 3 | G16: =D16*(E16+F16) -> 50000 | H16: 266.66667 | I16: 333.33333 | J16: 700 | L16: 233.33 | M16: 600 | N16: 1166
B17: 43057 | D17: 1000 | E17: 47 | F17: 3 | G17: =D17*(E17+F17) -> 50000 | L17: 233.33 | M17: 600 | N17: 1166
B18: 43058 | D18: 1000 | E18: 47 | F18: 3 | G18: =D18*(E18+F18) -> 50000 | L18: 233.33 | M18: 600 | N18: 1166
B19: 43059 | D19: 1000 | E19: 47 | F19: 3 | G19: =D19*(E19+F19) -> 50000 | L19: 233.33 | M19: 600 | N19: 1166
B20: 43060 | D20: 1000 | E20: 47 | F20: 3 | G20: =D20*(E20+F20) -> 50000 | L20: 233.33 | M20: 600 | N20: 1166
B21: 43061 | D21: 1000 | E21: 47 | F21: 3 | G21: =D21*(E21+F21) -> 50000 | L21: 233.33 | M21: 600 | N21: 1166
B22: 43062 | D22: 1000 | E22: 47 | F22: 3 | G22: =D22*(E22+F22) -> 50000
B23: 43063 | D23: 1000 | E23: 47 | F23: 3 | G23: =D23*(E23+F23) -> 50000
B24: 43064 | D24: 1000 | E24: 47 | F24: 3 | G24: =D24*(E24+F24) -> 50000
B25: 43065 | D25: 1000 | E25: 47 | F25: 3 | G25: =D25*(E25+F25) -> 50000
B26: 43066 | D26: 1000 | E26: 47 | F26: 3 | G26: =D26*(E26+F26) -> 50000
B27: 43067 | D27: 1000 | E27: 47 | F27: 3 | G27: =D27*(E27+F27) -> 50000
B28: 43068 | D28: 1000 | E28: 47 | F28: 3 | G28: =D28*(E28+F28) -> 50000
B29: 43069 | D29: 1000 | E29: 47 | F29: 3 | G29: =D29*(E29+F29) -> 50000
B30: 43070 | D30: 1000 | E30: 47 | F30: 3 | G30: =D30*(E30+F30) -> 50000
B31: 43071 | D31: 1000 | E31: 47 | F31: 3 | G31: =D31*(E31+F31) -> 50000
B32: 43072 | D32: 1000 | E32: 47 | F32: 3 | G32: =D32*(E32+F32) -> 50000
B33: 43073 | D33: 1000 | E33: 47 | F33: 3 | G33: =D33*(E33+F33) -> 50000
B34: 43074 | D34: 1000 | E34: 47 | F34: 3 | G34: =D34*(E34+F34) -> 50000
B35: 43075 | G35: =D35*(E35+F35) -> 0
B36: 43076
B37: 43077
B38: 43078
B39: 43079
B40: 43080
B41: 43081
...

Sheet Daily Progress Sheet
S2: Factory
B3: Date | C3: Article | D3: Quantity | E3: Amount/ Piece | F3: Kaaj/ Button | G3: Amount | H3: Elect | I3: SSGC | J3: Security | K3: Sweeper | L3: MIS | M3: Rent | N3: Transp | O3: Mechanic | P3: Helper/ Loader | Q3: Supp | R3: Total | S3: Amount/ Piece | T3: Total | U3: Profit
B4: 43045 | C4: 1 | D4: 13000 | E4: 75 | G4: =D4*(E4+F4) -> 975000 | H4: 15000 | K4: 5000 | L4: 20000 | M4: 35000 | N4: 15000 | O4: 5000 | P4: 20000 | Q4: 40000 | R4: =G4+H4+I4+J4+K4+L4+M4+N4+O4+P4+Q4 -> 1130000 | S4: 100 | T4: =S4*D4 -> 1300000 | U4: =T4-R4 -> 170000
B5: 43046 | C5: 1 | G5: =D5*(E5+F5) -> 0 | M5: =10*D5 -> 0 | R5: =G5+H5+L5+M5+O5+P5+Q5 -> 0 | T5: =S5*D5 -> 0 | U5: =T5-R5 -> 0
B6: 43047 | C6: 1 | G6: =D6*(E6+F6) -> 0 | M6: =10*D6 -> 0 | R6: =G6+H6+L6+M6+O6+P6+Q6 -> 0 | T6: =S6*D6 -> 0 | U6: =T6-R6 -> 0
B7: 43048 | C7: 1 | G7: =D7*(E7+F7) -> 0 | M7: =10*D7 -> 0 | R7: =G7+H7+L7+M7+O7+P7+Q7 -> 0 | T7: =S7*D7 -> 0 | U7: =T7-R7 -> 0
B8: 43049 | C8: 1 | G8: =D8*(E8+F8) -> 0 | M8: =10*D8 -> 0 | R8: =G8+H8+L8+M8+O8+P8+Q8 -> 0 | T8: =S8*D8 -> 0 | U8: =T8-R8 -> 0
B9: 43050 | C9: 1 | G9: =D9*(E9+F9) -> 0 | M9: =10*D9 -> 0 | R9: =G9+H9+L9+M9+O9+P9+Q9 -> 0 | T9: =S9*D9 -> 0 | U9: =T9-R9 -> 0
B10: 43051 | C10: 1 | G10: =D10*(E10+F10) -> 0 | M10: =10*D10 -> 0 | R10: =G10+H10+L10+M10+O10+P10+Q10 -> 0 | T10: =S10*D10 -> 0 | U10: =T10-R10 -> 0
B11: 43052 | C11: 1 | G11: =D11*(E11+F11) -> 0 | M11: =10*D11 -> 0 | R11: =G11+H11+L11+M11+O11+P11+Q11 -> 0 | T11: =S11*D11 -> 0 | U11: =T11-R11 -> 0
B12: 43053 | C12: 1 | G12: =D12*(E12+F12) -> 0 | M12: =10*D12 -> 0 | R12: =G12+H12+L12+M12+O12+P12+Q12 -> 0 | T12: =S12*D12 -> 0 | U12: =T12-R12 -> 0
B13: 43054 | C13: 1 | G13: =D13*(E13+F13) -> 0 | M13: =10*D13 -> 0 | R13: =G13+H13+L13+M13+O13+P13+Q13 -> 0 | T13: =S13*D13 -> 0 | U13: =T13-R13 -> 0
B14: 43055 | C14: 1 | G14: =D14*(E14+F14) -> 0 | M14: =10*D14 -> 0 | R14: =G14+H14+L14+M14+O14+P14+Q14 -> 0 | T14: =S14*D14 -> 0 | U14: =T14-R14 -> 0
B15: 43056 | C15: 1 | G15: =D15*(E15+F15) -> 0 | M15: =10*D15 -> 0 | R15: =G15+H15+L15+M15+O15+P15+Q15 -> 0 | T15: =S15*D15 -> 0 | U15: =T15-R15 -> 0
B16: 43057 | C16: 1 | G16: =D16*(E16+F16) -> 0 | M16: =10*D16 -> 0 | R16: =G16+H16+L16+M16+O16+P16+Q16 -> 0 | T16: =S16*D16 -> 0 | U16: =T16-R16 -> 0
... B18: 43059 | C18: 1 | G18: =D18*(E18+F18) -> 0 | M18: =10*D18 -> 0 | R18: =G18+H18+L18+M18+O18+P18+Q18 -> 0 | T18: =S18*D18 -> 0 | U18: =T18-R18 -> 0
B19: 43060 | G19: =D19*(E19+F19) -> 0 | M19: =10*D19 -> 0 | R19: =G19+H19+L19+M19+O19+P19+Q19 -> 0 | T19: =S19*D19 -> 0 | U19: =T19-R19 -> 0
B20: 43061 | G20: =D20*(E20+F20) -> 0 | M20: =10*D20 -> 0 | R20: =G20+H20+L20+M20+O20+P20+Q20 -> 0 | T20: =S20*D20 -> 0 | U20: =T20-R20 -> 0
B21: 43062 | G21: =D21*(E21+F21) -> 0 | M21: =10*D21 -> 0 | R21: =G21+H21+L21+M21+O21+P21+Q21 -> 0 | T21: =S21*D21 -> 0 | U21: =T21-R21 -> 0
B22: 43063 | G22: =D22*(E22+F22) -> 0 | M22: =10*D22 -> 0 | R22: =G22+H22+L22+M22+O22+P22+Q22 -> 0 | T22: =S22*D22 -> 0 | U22: =T22-R22 -> 0
B23: 43064 | G23: =D23*(E23+F23) -> 0 | M23: =10*D23 -> 0 | R23: =G23+H23+L23+M23+O23+P23+Q23 -> 0 | T23: =S23*D23 -> 0 | U23: =T23-R23 -> 0
B24: 43065 | G24: =D24*(E24+F24) -> 0 | M24: =10*D24 -> 0 | R24: =G24+H24+L24+M24+O24+P24+Q24 -> 0 | T24: =S24*D24 -> 0 | U24: =T24-R24 -> 0
B25: 43066 | G25: =D25*(E25+F25) -> 0 | M25: =10*D25 -> 0 | R25: =G25+H25+L25+M25+O25+P25+Q25 -> 0 | T25: =S25*D25 -> 0 | U25: =T25-R25 -> 0
B26: 43067 | G26: =D26*(E26+F26) -> 0 | M26: =10*D26 -> 0 | R26: =G26+H26+L26+M26+O26+P26+Q26 -> 0 | T26: =S26*D26 -> 0 | U26: =T26-R26 -> 0
B27: 43068 | G27: =D27*(E27+F27) -> 0 | M27: =10*D27 -> 0 | R27: =G27+H27+L27+M27+O27+P27+Q27 -> 0 | T27: =S27*D27 -> 0 | U27: =T27-R27 -> 0
B28: 43069 | G28: =D28*(E28+F28) -> 0 | M28: =10*D28 -> 0 | R28: =G28+H28+L28+M28+O28+P28+Q28 -> 0 | T28: =S28*D28 -> 0 | U28: =T28-R28 -> 0
B29: 43070 | G29: =D29*(E29+F29) -> 0 | M29: =10*D29 -> 0 | R29: =G29+H29+L29+M29+O29+P29+Q29 -> 0 | T29: =S29*D29 -> 0 | U29: =T29-R29 -> 0
B30: 43071 | G30: =D30*(E30+F30) -> 0 | M30: =10*D30 -> 0 | R30: =G30+H30+L30+M30+O30+P30+Q30 -> 0 | T30: =S30*D30 -> 0 | U30: =T30-R30 -> 0
... B38: 43079 | G38: =D38*(E38+F38) -> 0 | M38: =10*D38 -> 0 | R38: =G38+H38+L38+M38+O38+P38+Q38 -> 0 | T38: =S38*D38 -> 0 | U38: =T38-R38 -> 0
B40: Total | D40: =SUM(D4:D38) -> 13000 | E40: 75 | G40: =D40*(E40+F40) -> 975000 | H40: =SUM(H4:H38) -> 15000 | I40: =SUM(I4:I38) -> 0 | J40: =SUM(J4:J38) -> 0 | K40: =SUM(K4:K38) -> 5000 | L40: =SUM(L4:L38) -> 20000 | M40: =SUM(M4:M38) -> 35000 | N40: =SUM(N4:N38) -> 15000 | O40: =SUM(O4:O38) -> 5000 | ... Q40: =SUM(Q4:Q38) -> 40000 | R40: =G40+H40+I40+J40+K40+L40+M40+N40+O40+P40+Q40 -> 1130000 | S40: 100 | T40: =S40*D40 -> 1300000 | U40: =T40-R40 -> 170000
E45: Note
F46: Helper > one Driver and Two Helper salary min 15,000
F47: Supervioser >One suppervioser need per Floor Salary 40,000
F48: Security Gards >Tow Guards are required each salary 20,000
F49: Rent >8 PKR per piece
F50: Production per Day > 2500 Piece

Sheet CMT
B2: CMT
B3: Date | C3: Article | D3: Quantity | E3: Total amount | F3: Amount/ Piece | G3: Traed | H3: Cutting | I3: Kaaj/ Button | J3: shard card | K3: color | L3: Bukram | M3: prees | N3: Amount | O3: Elect | P3: Fule | Q3: Security | R3: Sweeper | S3: MIS | T3: Rent | U3: Transp | V3: Mechanic | W3: Helper/ Loader | X3: Chaker | Y3: Supp | Z3: QC | AA3: Incharge | AB3: HR/Acc | AC3: Total | AD3: Amount/ Piece | AE3: Total | AF3: Profit
B4: 45931 | C4: 1 | D4: 10000 | E4: =F4+G4+H4+I4+J4+K4+L4+M4 -> 267 | F4: 140 | G4: 22 | H4: 15 | I4: 15 | J4: 11 | K4: 6 | L4: 40 | M4: 18 | N4: =D4*E4 -> 2670000 | O4: 20000 | P4: 5000 | R4: 500 | V4: 1000 | W4: 16000 | AC4: =N4+O4+P4+Q4+R4+S4+T4+U4+V4+W4+X4+Y4+Z4+AA4+AB4 -> 2712500 | AD4: 330 | AE4: =AD4*D4 -> 3300000 | AF4: =AE4-AC4 -> 587500
B5: =B4+1 -> 45932 | C5: 1 | D5: 2000 | F5: 54 | N5: =D5*(F5+I5) -> 108000 | Q5: 16000 | W5: 16000 | AC5: =N5+O5+P5+Q5+R5+S5+T5+U5+V5+W5+X5+Y5+Z5+AA5+AB5 -> 140000 | AD5: 82 | AE5: =AD5*D5 -> 164000 | AF5: =AE5-AC5 -> 24000
B6: =B5+1 -> 45933 | C6: 1 | D6: 2000 | F6: 54 | N6: =D6*(F6+I6) -> 108000 | AC6: =N6+O6+P6+Q6+R6+S6+T6+U6+V6+W6+X6+Y6+Z6+AA6+AB6 -> 108000 | AD6: 82 | AE6: =AD6*D6 -> 164000 | AF6: =AE6-AC6 -> 56000
B7: =B6+1 -> 45934 | C7: 1 | D7: 2000 | F7: 54 | N7: =D7*(F7+I7) -> 108000 | AC7: =N7+O7+P7+Q7+R7+S7+T7+U7+V7+W7+X7+Y7+Z7+AA7+AB7 -> 108000 | AD7: 82 | AE7: =AD7*D7 -> 164000 | AF7: =AE7-AC7 -> 56000
B8: =B7+1 -> 45935 | C8: 1 | D8: 2000 | F8: 54 | N8: =D8*(F8+I8) -> 108000 | AC8: =N8+O8+P8+Q8+R8+S8+T8+U8+V8+W8+X8+Y8+Z8+AA8+AB8 -> 108000 | AD8: 82 | AE8: =AD8*D8 -> 164000 | AF8: =AE8-AC8 -> 56000
B9: =B8+1 -> 45936 | D9: 2000 | F9: 54 | N9: =D9*(F9+I9) -> 108000 | AC9: =N9+O9+P9+Q9+R9+S9+T9+U9+V9+W9+X9+Y9+Z9+AA9+AB9 -> 108000 | AD9: 82 | AE9: =AD9*D9 -> 164000 | AF9: =AE9-AC9 -> 56000
B10: =B9+1 -> 45937 | C10: 1 | N10: =D10*(F10+I10) -> 0 | AC10: =N10+O10+P10+Q10+R10+S10+T10+U10+V10+W10+X10+Y10+Z10+AA10+AB10 -> 0 | AE10: =AD10*D10 -> 0 | AF10: =AE10-AC10 -> 0
B11: =B10+1 -> 45938 | C11: 1 | D11: 2000 | F11: 54 | N11: =D11*(F11+I11) -> 108000 | AC11: =N11+O11+P11+Q11+R11+S11+T11+U11+V11+W11+X11+Y11+Z11+AA11+AB11 -> 108000 | AD11: 82 | AE11: =AD11*D11 -> 164000 | AF11: =AE11-AC11 -> 56000
B12: =B11+1 -> 45939 | C12: 1 | D12: 2000 | F12: 54 | N12: =D12*(F12+I12) -> 108000 | AC12: =N12+O12+P12+Q12+R12+S12+T12+U12+V12+W12+X12+Y12+Z12+AA12+AB12 -> 108000 | AD12: 82 | AE12: =AD12*D12 -> 164000 | AF12: =AE12-AC12 -> 56000
B13: =B12+1 -> 45940 | C13: 1 | D13: 2000 | F13: 54 | N13: =D13*(F13+I13) -> 108000 | AC13: =N13+O13+P13+Q13+R13+S13+T13+U13+V13+W13+X13+Y13+Z13+AA13+AB13 -> 108000 | AD13: 82 | AE13: =AD13*D13 -> 164000 | AF13: =AE13-AC13 -> 56000
B14: =B13+1 -> 45941 | C14: 1 | D14: 2000 | F14: 54 | N14: =D14*(F14+I14) -> 108000 | AC14: =N14+O14+P14+Q14+R14+S14+T14+U14+V14+W14+X14+Y14+Z14+AA14+AB14 -> 108000 | AD14: 82 | AE14: =AD14*D14 -> 164000 | AF14: =AE14-AC14 -> 56000
B15: =B14+1 -> 45942 | C15: 1 | D15: 2000 | F15: 54 | N15: =D15*(F15+I15) -> 108000 | AC15: =N15+O15+P15+Q15+R15+S15+T15+U15+V15+W15+X15+Y15+Z15+AA15+AB15 -> 108000 | AD15: 82 | AE15: =AD15*D15 -> 164000 | AF15: =AE15-AC15 -> 56000
B16: =B15+1 -> 45943 | C16: 1 | D16: 2000 | F16: 54 | N16: =D16*(F16+I16) -> 108000 | AC16: =N16+O16+P16+Q16+R16+S16+T16+U16+V16+W16+X16+Y16+Z16+AA16+AB16 -> 108000 | AD16: 82 | AE16: =AD16*D16 -> 164000 | AF16: =AE16-AC16 -> 56000
B17: =B16+1 -> 45944 | C17: 1 | N17: =D17*(F17+I17) -> 0 | AC17: =N17+O17+P17+Q17+R17+S17+T17+U17+V17+W17+X17+Y17+Z17+AA17+AB17 -> 0 | AE17: =AD17*D17 -> 0 | AF17: =AE17-AC17 -> 0
B18: =B17+1 -> 45945 | C18: 1 | D18: 2000 | F18: 54 | N18: =D18*(F18+I18) -> 108000 | AC18: =N18+O18+P18+Q18+R18+S18+T18+U18+V18+W18+X18+Y18+Z18+AA18+AB18 -> 108000 | AD18: 82 | AE18: =AD18*D18 -> 164000 | AF18: =AE18-AC18 -> 56000
B19: =B18+1 -> 45946 | D19: 2000 | F19: 54 | N19: =D19*(F19+I19) -> 108000 | AC19: =N19+O19+P19+Q19+R19+S19+T19+U19+V19+W19+X19+Y19+Z19+AA19+AB19 -> 108000 | AD19: 82 | AE19: =AD19*D19 -> 164000 | AF19: =AE19-AC19 -> 56000
B20: =B19+1 -> 45947 | D20: 2000 | F20: 54 | N20: =D20*(F20+I20) -> 108000 | AC20: =N20+O20+P20+Q20+R20+S20+T20+U20+V20+W20+X20+Y20+Z20+AA20+AB20 -> 108000 | AD20: 82 | AE20: =AD20*D20 -> 164000 | AF20: =AE20-AC20 -> 56000
B21: =B20+1 -> 45948 | D21: 2000 | F21: 54 | N21: =D21*(F21+I21) -> 108000 | AC21: =N21+O21+P21+Q21+R21+S21+T21+U21+V21+W21+X21+Y21+Z21+AA21+AB21 -> 108000 | AD21: 82 | AE21: =AD21*D21 -> 164000 | AF21: =AE21-AC21 -> 56000
B22: =B21+1 -> 45949 | D22: 2000 | F22: 54 | N22: =D22*(F22+I22) -> 108000 | AC22: =N22+O22+P22+Q22+R22+S22+T22+U22+V22+W22+X22+Y22+Z22+AA22+AB22 -> 108000 | AD22: 82 | AE22: =AD22*D22 -> 164000 | AF22: =AE22-AC22 -> 56000
B23: =B22+1 -> 45950 | D23: 2000 | F23: 54 | N23: =D23*(F23+I23) -> 108000 | AC23: =N23+O23+P23+Q23+R23+S23+T23+U23+V23+W23+X23+Y23+Z23+AA23+AB23 -> 108000 | AD23: 82 | AE23: =AD23*D23 -> 164000 | AF23: =AE23-AC23 -> 56000
B24: =B23+1 -> 45951 | N24: =D24*(F24+I24) -> 0 | AC24: =N24+O24+P24+Q24+R24+S24+T24+U24+V24+W24+X24+Y24+Z24+AA24+AB24 -> 0 | AD24: 165 | AE24: =AD24*D24 -> 0 | AF24: =AE24-AC24 -> 0
B25: =B24+1 -> 45952 | D25: 2000 | F25: 54 | N25: =D25*(F25+I25) -> 108000 | AC25: =N25+O25+P25+Q25+R25+S25+T25+U25+V25+W25+X25+Y25+Z25+AA25+AB25 -> 108000 | AD25: 82 | AE25: =AD25*D25 -> 164000 | AF25: =AE25-AC25 -> 56000
B26: =B25+1 -> 45953 | D26: 2000 | F26: 54 | N26: =D26*(F26+I26) -> 108000 | AC26: =N26+O26+P26+Q26+R26+S26+T26+U26+V26+W26+X26+Y26+Z26+AA26+AB26 -> 108000 | AD26: 82 | AE26: =AD26*D26 -> 164000 | AF26: =AE26-AC26 -> 56000
B27: =B26+1 -> 45954 | D27: 2000 | F27: 54 | N27: =D27*(F27+I27) -> 108000 | AC27: =N27+O27+P27+Q27+R27+S27+T27+U27+V27+W27+X27+Y27+Z27+AA27+AB27 -> 108000 | AD27: 82 | AE27: =AD27*D27 -> 164000 | AF27: =AE27-AC27 -> 56000
B28: =B27+1 -> 45955 | D28: 2000 | F28: 54 | N28: =D28*(F28+I28) -> 108000 | AC28: =N28+O28+P28+Q28+R28+S28+T28+U28+V28+W28+X28+Y28+Z28+AA28+AB28 -> 108000 | AD28: 82 | AE28: =AD28*D28 -> 164000 | AF28: =AE28-AC28 -> 56000
B29: =B28+1 -> 45956 | D29: 2000 | F29: 54 | N29: =D29*(F29+I29) -> 108000 | AC29: =N29+O29+P29+Q29+R29+S29+T29+U29+V29+W29+X29+Y29+Z29+AA29+AB29 -> 108000 | AD29: 82 | AE29: =AD29*D29 -> 164000 | AF29: =AE29-AC29 -> 56000
B30: =B29+1 -> 45957 | D30: 2000 | F30: 54 | N30: =D30*(F30+I30) -> 108000 | AC30: =N30+O30+P30+Q30+R30+S30+T30+U30+V30+W30+X30+Y30+Z30+AA30+AB30 -> 108000 | AD30: 82 | AE30: =AD30*D30 -> 164000 | AF30: =AE30-AC30 -> 56000
B31: =B30+1 -> 45958 | N31: =D31*(F31+I31) -> 0 | AC31: =N31+O31+P31+Q31+R31+S31+T31+U31+V31+W31+X31+Y31+Z31+AA31+AB31 -> 0 | AD31: 165 | AE31: =AD31*D31 -> 0 | AF31: =AE31-AC31 -> 0
B32: =B31+1 -> 45959 | D32: 2000 | F32: 54 | N32: =D32*(F32+I32) -> 108000 | AC32: =N32+O32+P32+Q32+R32+S32+T32+U32+V32+W32+X32+Y32+Z32+AA32+AB32 -> 108000 | AD32: 82 | AE32: =AD32*D32 -> 164000 | AF32: =AE32-AC32 -> 56000
B33: =B32+1 -> 45960 | D33: 2000 | F33: 54 | N33: =D33*(F33+I33) -> 108000 | AC33: =N33+O33+P33+Q33+R33+S33+T33+U33+V33+W33+X33+Y33+Z33+AA33+AB33 -> 108000 | AD33: 82 | AE33: =AD33*D33 -> 164000 | AF33: =AE33-AC33 -> 56000
B34: =B33+1 -> 45961 | N34: =D34*(F34+I34) -> 0 | AC34: =N34+O34+S34+T34+V34+W34+Y34 -> 0 | AE34: =AD34*D34 -> 0 | AF34: =AE34-AC34 -> 0
B36: Total | D36: =SUM(D4:D34) -> 60000 | F36: 54 | N36: =D36*(F36+I36) -> 3240000 | O36: =SUM(O4:O34) -> 20000 | P36: =SUM(P4:P34) -> 5000 | Q36: =SUM(Q4:Q34) -> 16000 | R36: =SUM(R4:R34) -> 500 | S36: =SUM(S4:S34) -> 0 | T36: =SUM(T4:T34) -> 0 | U36: =SUM(U4:U34) -> 0 | V36: =SUM(V4:V34) -> 1000 | ... AB36: =SUM(AB4:AB34) -> 0 | AC36: =N36+O36+P36+Q36+R36+S36+T36+U36+V36+W36+X36+Y36+Z36+AA36+AB36 -> 3314500 | AD36: 82 | AE36: =AD36*D36 -> 4920000 | AF36: =AE36-AC36 -> 1605500
F41: Note
I42: Helper > one Driver and Two Helper salary min 15,000
I43: Supervioser >One suppervioser need per Floor Salary 40,000
I44: Security Gards >Tow Guards are required each salary 20,000
I45: Rent >8 PKR per piece
I46: Production per Day > 2500 Piece
...

Sheet Self Made 
S2: Factory
B3: Date | C3: Article | D3: Quantity | E3: Amount/ Piece | F3: Kaaj/ Button | G3: Amount | H3: Elect | I3: SSGC | J3: Security | K3: Sweeper | L3: MIS | M3: Rent | N3: Transp | O3: Mechanic | P3: Helper/ Loader | Q3: Supp | R3: Total | S3: Amount/ Piece | T3: Total | U3: Profit
B4: 43045 | C4: 1 | D4: 150 | E4: 115 | G4: =D4*(E4+F4) -> 17250 | K4: 5000 | L4: 20000 | M4: 35000 | N4: 15000 | O4: 5000 | P4: 20000 | Q4: 40000 | R4: =G4+H4+I4+J4+K4+L4+M4+N4+O4+P4+Q4 -> 157250 | S4: 100 | T4: =S4*D4 -> 15000 | U4: =T4-R4 -> -142250
B5: 43046 | C5: 1 | D5: 150 | E5: 115 | G5: =D5*(E5+F5) -> 17250 | M5: =10*D5 -> 1500 | R5: =G5+H5+L5+M5+O5+P5+Q5 -> 18750 | T5: =S5*D5 -> 0 | U5: =T5-R5 -> -18750
B6: 43047 | C6: 1 | D6: 150 | E6: 115 | G6: =D6*(E6+F6) -> 17250 | M6: =10*D6 -> 1500 | R6: =G6+H6+L6+M6+O6+P6+Q6 -> 18750 | T6: =S6*D6 -> 0 | U6: =T6-R6 -> -18750
B7: 43048 | C7: 1 | D7: 150 | E7: 115 | G7: =D7*(E7+F7) -> 17250 | M7: =10*D7 -> 1500 | R7: =G7+H7+L7+M7+O7+P7+Q7 -> 18750 | T7: =S7*D7 -> 0 | U7: =T7-R7 -> -18750
B8: 43049 | C8: 1 | D8: 150 | E8: 115 | G8: =D8*(E8+F8) -> 17250 | M8: =10*D8 -> 1500 | R8: =G8+H8+L8+M8+O8+P8+Q8 -> 18750 | T8: =S8*D8 -> 0 | U8: =T8-R8 -> -18750
B9: 43050 | C9: 1 | D9: 150 | E9: 115 | G9: =D9*(E9+F9) -> 17250 | M9: =10*D9 -> 1500 | R9: =G9+H9+L9+M9+O9+P9+Q9 -> 18750 | T9: =S9*D9 -> 0 | U9: =T9-R9 -> -18750
B10: 43051 | C10: 1 | D10: 150 | E10: 115 | G10: =D10*(E10+F10) -> 17250 | M10: =10*D10 -> 1500 | R10: =G10+H10+L10+M10+O10+P10+Q10 -> 18750 | T10: =S10*D10 -> 0 | U10: =T10-R10 -> -18750
B11: 43052 | C11: 1 | D11: 150 | E11: 115 | G11: =D11*(E11+F11) -> 17250 | M11: =10*D11 -> 1500 | R11: =G11+H11+L11+M11+O11+P11+Q11 -> 18750 | T11: =S11*D11 -> 0 | U11: =T11-R11 -> -18750
B12: 43053 | C12: 1 | D12: 150 | E12: 115 | G12: =D12*(E12+F12) -> 17250 | M12: =10*D12 -> 1500 | R12: =G12+H12+L12+M12+O12+P12+Q12 -> 18750 | T12: =S12*D12 -> 0 | U12: =T12-R12 -> -18750
B13: 43054 | C13: 1 | D13: 150 | E13: 115 | G13: =D13*(E13+F13) -> 17250 | M13: =10*D13 -> 1500 | R13: =G13+H13+L13+M13+O13+P13+Q13 -> 18750 | T13: =S13*D13 -> 0 | U13: =T13-R13 -> -18750
B14: 43055 | C14: 1 | D14: 150 | E14: 115 | G14: =D14*(E14+F14) -> 17250 | M14: =10*D14 -> 1500 | R14: =G14+H14+L14+M14+O14+P14+Q14 -> 18750 | T14: =S14*D14 -> 0 | U14: =T14-R14 -> -18750
B15: 43056 | C15: 1 | D15: 150 | E15: 115 | G15: =D15*(E15+F15) -> 17250 | M15: =10*D15 -> 1500 | R15: =G15+H15+L15+M15+O15+P15+Q15 -> 18750 | T15: =S15*D15 -> 0 | U15: =T15-R15 -> -18750
B16: 43057 | C16: 1 | D16: 150 | E16: 115 | G16: =D16*(E16+F16) -> 17250 | M16: =10*D16 -> 1500 | R16: =G16+H16+L16+M16+O16+P16+Q16 -> 18750 | T16: =S16*D16 -> 0 | U16: =T16-R16 -> -18750
... B18: 43059 | C18: 1 | D18: 150 | E18: 115 | G18: =D18*(E18+F18) -> 17250 | M18: =10*D18 -> 1500 | R18: =G18+H18+L18+M18+O18+P18+Q18 -> 18750 | T18: =S18*D18 -> 0 | U18: =T18-R18 -> -18750
B19: 43060 | D19: 150 | E19: 115 | G19: =D19*(E19+F19) -> 17250 | M19: =10*D19 -> 1500 | R19: =G19+H19+L19+M19+O19+P19+Q19 -> 18750 | T19: =S19*D19 -> 0 | U19: =T19-R19 -> -18750
B20: 43061 | D20: 150 | E20: 115 | G20: =D20*(E20+F20) -> 17250 | M20: =10*D20 -> 1500 | R20: =G20+H20+L20+M20+O20+P20+Q20 -> 18750 | T20: =S20*D20 -> 0 | U20: =T20-R20 -> -18750
B21: 43062 | D21: 150 | E21: 115 | G21: =D21*(E21+F21) -> 17250 | M21: =10*D21 -> 1500 | R21: =G21+H21+L21+M21+O21+P21+Q21 -> 18750 | T21: =S21*D21 -> 0 | U21: =T21-R21 -> -18750
B22: 43063 | D22: 150 | E22: 115 | G22: =D22*(E22+F22) -> 17250 | M22: =10*D22 -> 1500 | R22: =G22+H22+L22+M22+O22+P22+Q22 -> 18750 | T22: =S22*D22 -> 0 | U22: =T22-R22 -> -18750
B23: 43064 | D23: 150 | E23: 115 | G23: =D23*(E23+F23) -> 17250 | M23: =10*D23 -> 1500 | R23: =G23+H23+L23+M23+O23+P23+Q23 -> 18750 | T23: =S23*D23 -> 0 | U23: =T23-R23 -> -18750
B24: 43065 | D24: 150 | E24: 115 | G24: =D24*(E24+F24) -> 17250 | M24: =10*D24 -> 1500 | R24: =G24+H24+L24+M24+O24+P24+Q24 -> 18750 | T24: =S24*D24 -> 0 | U24: =T24-R24 -> -18750
B25: 43066 | D25: 150 | E25: 115 | G25: =D25*(E25+F25) -> 17250 | M25: =10*D25 -> 1500 | R25: =G25+H25+L25+M25+O25+P25+Q25 -> 18750 | T25: =S25*D25 -> 0 | U25: =T25-R25 -> -18750
B26: 43067 | D26: 150 | E26: 115 | G26: =D26*(E26+F26) -> 17250 | M26: =10*D26 -> 1500 | R26: =G26+H26+L26+M26+O26+P26+Q26 -> 18750 | T26: =S26*D26 -> 0 | U26: =T26-R26 -> -18750
B27: 43068 | D27: 150 | E27: 115 | G27: =D27*(E27+F27) -> 17250 | M27: =10*D27 -> 1500 | R27: =G27+H27+L27+M27+O27+P27+Q27 -> 18750 | T27: =S27*D27 -> 0 | U27: =T27-R27 -> -18750
B28: 43069 | D28: 150 | E28: 115 | G28: =D28*(E28+F28) -> 17250 | M28: =10*D28 -> 1500 | R28: =G28+H28+L28+M28+O28+P28+Q28 -> 18750 | T28: =S28*D28 -> 0 | U28: =T28-R28 -> -18750
B29: 43070 | D29: 150 | E29: 115 | G29: =D29*(E29+F29) -> 17250 | M29: =10*D29 -> 1500 | R29: =G29+H29+L29+M29+O29+P29+Q29 -> 18750 | T29: =S29*D29 -> 0 | U29: =T29-R29 -> -18750
B30: 43071 | D30: 150 | E30: 115 | G30: =D30*(E30+F30) -> 17250 | M30: =10*D30 -> 1500 | R30: =G30+H30+L30+M30+O30+P30+Q30 -> 18750 | T30: =S30*D30 -> 0 | U30: =T30-R30 -> -18750
... B38: 43079 | D38: 150 | E38: 115 | G38: =D38*(E38+F38) -> 17250 | M38: =10*D38 -> 1500 | R38: =G38+H38+L38+M38+O38+P38+Q38 -> 18750 | T38: =S38*D38 -> 0 | U38: =T38-R38 -> -18750
B40: Total | D40: =SUM(D4:D38) -> 5250 | E40: 75 | G40: =D40*(E40+F40) -> 393750 | H40: =SUM(H4:H38) -> 0 | I40: =SUM(I4:I38) -> 0 | J40: =SUM(J4:J38) -> 0 | K40: =SUM(K4:K38) -> 5000 | L40: =SUM(L4:L38) -> 20000 | M40: =SUM(M4:M38) -> 86000 | N40: =SUM(N4:N38) -> 15000 | O40: =SUM(O4:O38) -> 5000 | ... Q40: =SUM(Q4:Q38) -> 40000 | R40: =G40+H40+I40+J40+K40+L40+M40+N40+O40+P40+Q40 -> 584750 | S40: 100 | T40: =S40*D40 -> 525000 | U40: =T40-R40 -> -59750
L41: Self made
E45: Note
F46: Helper > one Driver and Two Helper salary min 15,000
F47: Supervioser >One suppervioser need per Floor Salary 40,000
F48: Security Gards >Tow Guards are required each salary 20,000
F49: Rent >8 PKR per piece
F50: Production per Day > 2500 Piece

Sheet Sheet4
A3: Cloth | B3: Article | C3: Product | D3: Amout/ Meter | E3: Cloth/ Peace | F3: Cloth Amount/ peace | G3: Steaching/ peace | H3: embroidery/ peace | I3: washing/ Peace | J3: Cards & Leable | K3: Transport | L3: Mis | M3: Total | N3: Seal/Peace | O3: Profit/peace | P3: Total Peace | Q3: Total Profit
A4: Self prtint | B4: 8 | C4: 164 | D4: 250 | E4: 3.8 | F4: =D4*E4 -> 950 | G4: 350 | H4: 80 | I4: 0 | J4: 0 | L4: 75 | M4: =F4+G4+H4+I4+J4+K4+L4 -> 1455 | N4: 1700 | O4: =N4-M4 -> 245 | P4: 164 | Q4: =O4*P4 -> 40180
A5: Black Nated
A6: Colour Nated | B6: 1000 | C6: =B6/E6 -> 263.15789 | E6: 3.8 | G6: 140 | J6: 15
A8: Blue Saton | B8: 650 | C8: =B8/E8 -> 492.42424 | D8: 180 | E8: 1.32 | F8: =D8*E8 -> 237.6 | G8: 90 | H8: 8 | I8: 25 | J8: 5 | M8: =F8+G8+H8+I8+J8+K8+L8 -> 365.6 | N8: 400 | O8: =N8-M8 -> 34.4 | P8: 492 | Q8: =O8*P8 -> 16924.8
A9: Black Saton | B9: 650 | C9: =B9/E9 -> 492.42424 | D9: 185 | E9: 1.32 | F9: =D9*E9 -> 244.2 | G9: 90 | H9: 8 | I9: 25 | J9: 5 | M9: =F9+G9+H9+I9+J9+K9+L9 -> 372.2 | N9: 400 | O9: =N9-M9 -> 27.8 | P9: 492 | Q9: =O9*P9 -> 13677.6
A10: Colour Saton | B10: 650 | C10: =B10/E10 -> 492.42424 | D10: 190 | E10: 1.32 | F10: =D10*E10 -> 250.8 | G10: 90 | H10: 8 | I10: 25 | J10: 5 | M10: =F10+G10+H10+I10+J10+K10+L10 -> 378.8 | N10: 400 | O10: =N10-M10 -> 21.2 | P10: 492 | Q10: =O10*P10 -> 10430.4
A12: Mendis Blue | B12: 650 | C12: =B12/E12 -> 520 | D12: 150 | E12: 1.25 | F12: =D12*E12 -> 187.5 | G12: 80 | H12: 0 | I12: 12 | J12: 5 | M12: =F12+G12+H12+I12+J12+K12+L12 -> 284.5 | N12: 300 | O12: =N12-M12 -> 15.5 | P12: 520 | Q12: =O12*P12 -> 8060
A13: Mendis Black | B13: 650 | C13: =B13/E13 -> 520 | D13: 150 | E13: 1.25 | F13: =D13*E13 -> 187.5 | G13: 80 | H13: 0 | I13: 12 | J13: 5 | M13: =F13+G13+H13+I13+J13+K13+L13 -> 284.5 | N13: 300 | O13: =N13-M13 -> 15.5 | P13: 520 | Q13: =O13*P13 -> 8060

Sheet Sheet3
B3: Contractor Invoice
B4: Date | C4: Amount | D4: Receive | E4: Balance
B5: ='Daily Progress Sheet'!B4 -> 43045 | C5: ='Daily Progress Sheet'!G4 -> 975000 | E5: =C5-D5 -> 975000
B6: ='Daily Progress Sheet'!B5 -> 43046 | C6: ='Daily Progress Sheet'!G5 -> 0 | D6: 1000 | E6: =E5+C6-D6 -> 974000
B7: ='Daily Progress Sheet'!B6 -> 43047 | C7: ='Daily Progress Sheet'!G6 -> 0 | E7: =E6+C7-D7 -> 974000
B8: ='Daily Progress Sheet'!B7 -> 43048 | C8: ='Daily Progress Sheet'!G7 -> 0 | D8: 1000 | E8: =E7+C8-D8 -> 973000
B9: ='Daily Progress Sheet'!B8 -> 43049 | C9: ='Daily Progress Sheet'!G8 -> 0 | E9: =E8+C9-D9 -> 973000
B10: ='Daily Progress Sheet'!B9 -> 43050 | C10: ='Daily Progress Sheet'!G9 -> 0 | D10: 8000 | E10: =E9+C10-D10 -> 965000
B11: ='Daily Progress Sheet'!B10 -> 43051 | C11: ='Daily Progress Sheet'!G10 -> 0 | D11: 4000 | E11: =E10+C11-D11 -> 961000
B12: ='Daily Progress Sheet'!B11 -> 43052 | C12: ='Daily Progress Sheet'!G11 -> 0 | E12: =E11+C12-D12 -> 961000
B13: ='Daily Progress Sheet'!B12 -> 43053 | C13: ='Daily Progress Sheet'!G12 -> 0 | E13: =E12+C13-D13 -> 961000
B14: ='Daily Progress Sheet'!B13 -> 43054 | C14: ='Daily Progress Sheet'!G13 -> 0 | D14: 2000 | E14: =E13+C14-D14 -> 959000
B15: ='Daily Progress Sheet'!B14 -> 43055 | C15: ='Daily Progress Sheet'!G14 -> 0 | E15: =E14+C15-D15 -> 959000
B16: ='Daily Progress Sheet'!B15 -> 43056 | C16: ='Daily Progress Sheet'!G15 -> 0 | E16: =E15+C16-D16 -> 959000
B17: ='Daily Progress Sheet'!B16 -> 43057 | C17: ='Daily Progress Sheet'!G16 -> 0 | E17: =E16+C17-D17 -> 959000
B18: ='Daily Progress Sheet'!B17 -> 43058 | C18: ='Daily Progress Sheet'!G17 -> 0 | D18: 15000 | E18: =E17+C18-D18 -> 944000
B19: ='Daily Progress Sheet'!B18 -> 43059 | C19: ='Daily Progress Sheet'!G18 -> 0 | E19: =E18+C19-D19 -> 944000
B20: ='Daily Progress Sheet'!B19 -> 43060 | C20: ='Daily Progress Sheet'!G19 -> 0 | E20: =E19+C20-D20 -> 944000
B21: ='Daily Progress Sheet'!B20 -> 43061 | C21: ='Daily Progress Sheet'!G20 -> 0 | E21: =E20+C21-D21 -> 944000
B22: ='Daily Progress Sheet'!B21 -> 43062 | C22: ='Daily Progress Sheet'!G21 -> 0 | E22: =E21+C22-D22 -> 944000
B23: ='Daily Progress Sheet'!B22 -> 43063 | C23: ='Daily Progress Sheet'!G22 -> 0 | E23: =E22+C23-D23 -> 944000
B24: ='Daily Progress Sheet'!B23 -> 43064 | C24: ='Daily Progress Sheet'!G23 -> 0 | E24: =E23+C24-D24 -> 944000
B25: ='Daily Progress Sheet'!B24 -> 43065 | C25: ='Daily Progress Sheet'!G24 -> 0 | E25: =E24+C25-D25 -> 944000
B26: ='Daily Progress Sheet'!B25 -> 43066 | C26: ='Daily Progress Sheet'!G25 -> 0 | E26: =E25+C26-D26 -> 944000
B27: ='Daily Progress Sheet'!B26 -> 43067 | C27: ='Daily Progress Sheet'!G26 -> 0 | E27: =E26+C27-D27 -> 944000
B28: ='Daily Progress Sheet'!B27 -> 43068 | C28: ='Daily Progress Sheet'!G27 -> 0 | E28: =E27+C28-D28 -> 944000
B29: ='Daily Progress Sheet'!B28 -> 43069 | C29: ='Daily Progress Sheet'!G28 -> 0 | E29: =E28+C29-D29 -> 944000
B30: ='Daily Progress Sheet'!B29 -> 43070 | C30: ='Daily Progress Sheet'!G29 -> 0 | E30: =E29+C30-D30 -> 944000
... B34: ='Daily Progress Sheet'!B33 -> 43074 | C34: ='Daily Progress Sheet'!G33 -> 0 | E34: =E33+C34-D34 -> 944000
B35: 43070
B36: 43071 | D36: =SUM(D5:D35) -> 31000

Sheet Balance Sheet
A3: S No | B3: Date | C3: Description | D3: Amount Recive | E3: Used | F3: Balance
A12: 1 | B12: 43048 | C12: Kazmi Sent Farhan Account | D12: 10000 | F12: =D12-E12 -> 10000
A13: 2 | B13: 43048 | C13: Tea for Q.C of TF | E13: 50 | F13: 9950
A14: 3 | B14: 43048 | C14: Lunch | E14: 150 | F14: 9800
A15: 4 | B15: 43048 | C15: Cold drink 500 ML | E15: 50 | F15: 9750
A16: 5 | B16: 43048 | C16: Tea for Baying staff | E16: 50 | F16: 9700
A17: 6 | B17: 43048 | C17: Twiser two Piece | E17: 60 | F17: 9640
A18: 7 | B18: 43048 | C18: Elfi One piece | E18: 20 | F18: 9620
A19: 8 | B19: 43048 | C19: Niddle screw driver two piece | E19: 40 | F19: 9580
A20: 9 | B20: 43048 | C20: Feedo folder MH | E20: 500 | F20: 9080
A21: 10 | B21: 43048 | C21: Niddle screw Boot screw Niddle plate screw 12+12+12 | E21: 72 | F21: 9008
A22: 11 | B22: 43048 | C22: Niddle T v 5 19 no 1 Patta | E22: 130 | F22: 8878
A23: 12 | B23: 43048 | C23: Cleeper 6piece | E23: 150 | F23: 8728
A24: 13 | B24: 43048 | C24: Feedo looper pipe | E24: 20 | F24: 8708
... A33: 22 | B33: 43049 | C33: Feedo machine Niddle bar screw | E33: 15 | F33: 5299
A34: 23 | B34: 43050 | C34: Kazmi Sent Farhan Account | D34: 35000 | F34: 40299
A35: 24 | B35: 43050 | C35: Tea for all day | E35: 240 | F35: 40059
A36: 25 | B36: 43050 | C36: Cold drink 500 ML | E36: 50 | F36: 40009
A37: 26 | B37: 43050 | C37: Lunch | E37: 220 | F37: 39789
A38: 27 | B38: 43050 | C38: stationary | E38: 155 | F38: 39634
A39: 28 | B39: 43050 | C39: Gagan contector advance | E39: 8000 | F39: 31634
A40: 29 | B40: 43080 | C40: Factory rent for the month of November 2017 | E40: 21000 | F40: 10634
A41: 30 | B41: 43080 | C41: Gagan contector advance | E41: 4000 | F41: 6634
A42: 31 | B42: 13-11-2017 | C42: Kazmi Sent Farhan Account | D42: 20000 | F42: 26634
A43: 32 | B43: 13-11-17 | C43: Tea for all day | E43: 60 | F43: 26574
A44: 33 | B44: 13-11-17 | C44: Lunch | E44: 200 | F44: 26374
A45: 34 | B45: 43052 | C45: Open a drain line of factry | E45: 300 | F45: 26074
A46: 35 | B46: 43052 | C46: Electric plyer 1 piece | E46: 175 | F46: 25899
A47: 36 | B47: 43052 | C47: Mobile balance for shahid bhai | E47: 50 | F47: 25849
A48: 37 | B48: 43052 | C48: Bick petrol for factry to site area | E48: 100 | F48: 25749
A49: 38 | B49: 43052 | C49: Rubber roller for feedo machine for puller. | E49: 400 | F49: 25349
A50: 39 | B50: 43053 | C50: kansai machine niddle plate and boot repairing | E50: 300 | F50: 25049
A51: 40 | B51: 43053 | C51: Feedo machine boot rod and screw purchasing | E51: 125 | F51: 24924
A52: 41 | B52: 43053 | C52: Tea for all day | E52: 80 | F52: 24844
A53: 42 | B53: 43053 | C53: Lunch | E53: 200 | F53: 24644
A54: 43 | B54: 43053 | C54: Advance against salary to Mr shahid | E54: 10000 | F54: 14644
A55: 44 | B55: 43053 | C55: Bick petrol for factry to istar gate for labour arrangement | E55: 100 | F55: 14544
A56: 45 | B56: 14-11-2017 | C56: Arshad mecheninc Advance against salary | E56: 5000 | F56: 9544
A57: 46 | B57: 15-11-2017 | C57: Tea for all day | E57: 50 | F57: 9494
A58: 47 | B58: 15-11-2017 | C58: Lunch | E58: 230 | F58: 9264
...

Sheet Sheet2
B4: Machine | C4: Quantity | D4: Price | E4: Total Amount
B5: Singer | C5: 22 | D5: 45000 | E5: =C5*D5 -> 990000
B6: Two Niddle | C6: 4 | D6: 70000 | E6: =C6*D6 -> 280000
B7: Over Lock | C7: 2 | D7: 70000 | E7: =C7*D7 -> 140000
B8: Sefty | C8: 2 | D8: 75000 | E8: =C8*D8 -> 150000
B9: Consaee | C9: 1 | D9: 125000 | E9: =C9*D9 -> 125000
B10: Feedo | C10: 2 | D10: 175000 | E10: =C10*D10 -> 350000
B12: Total | C12: =SUM(C5:C11) -> 33 | E12: =SUM(E5:E11) -> 2035000

Sheet Balance Sheet (2)
A3: S No | B3: Date | C3: Description | D3: Amount Recive | E3: Used | F3: Balance
A4: 1 | B4: 42897 | C4: Advance against salary to Ejaz Helper | E4: 1000 | F4: =D4-E4 -> -1000
A5: 2 | B5: 42897 | C5: Lunch for Q.C of TF | E5: 320 | F5: =F4+D5-E5 -> -1320
A6: 3 | B6: 42897 | C6: color penciles two piece | E6: 20 | F6: =F5+D6-E6 -> -1340
A7: 4 | B7: 42897 | C7: Tea for Q.C of TF | E7: 60 | F7: =F6+D7-E7 -> -1400
A8: 5 | B8: 42897 | C8: V-Belt for Over lock machine | E8: 70 | F8: =F7+D8-E8 -> -1470
A9: 6 | B9: 42927 | C9: Advance against salary to Mr shahid | E9: 1000 | F9: =F8+D9-E9 -> -2470
A10: 7 | B10: 42927 | C10: Advane against salary to Mr Gagun | E10: 1000 | F10: =F9+D10-E10 -> -3470
A11: 8 | B11: 42927 | C11: Sweeper salary for the month of october 2017 | E11: 2500 | F11: =F10+D11-E11 -> -5970
A12: 9 | B12: 42927 | C12: Suzuki rent for TF to factry | E12: 1100 | F12: -7070
A13: 10 | B13: 42927 | C13: Bick petrol for factry to TF | E13: 100 | F13: -7170
A14: 11 | B14: 42927 | C14: Lunch | E14: 200 | F14: -7370
A15: 12 | B15: 42927 | C15: Moblile balance for plaining manager of TF | E15: 200 | F15: -7570
A16: 13 | B16: 42927 | C16: Pying amount of TF loader | E16: 100 | F16: -7670
A17: 14 | B17: 42958 | C17: crockery (soucers and spoons) | E17: 420 | F17: -8090
A18: 15 | B18: 42958 | C18: Tea and biscuts for TF QC | E18: 150 | F18: -8240
A19: 16 | B19: 42958 | C19: Tea for Guaistsa | E19: 110 | F19: -8350
A20: 17 | B20: 42958 | C20: Cold drink For TF QC | E20: 90 | F20: -8440
A21: 18 | B21: 43048 | C21: Kazmi Sent Farhan Account | D21: 10000 | F21: 1560
A22: 19 | B22: 43048 | C22: Tea for Q.C of TF | E22: 50 | F22: =F21+D22-E22 -> 1510
A23: 20 | B23: 43048 | C23: Lunch | E23: 150 | F23: =F22+D23-E23 -> 1360
A24: 21 | B24: 43048 | C24: Cold drink 500 ML | E24: 50 | F24: =F23+D24-E24 -> 1310
A25: 22 | B25: 43048 | C25: Tea for Baying staff | E25: 50 | F25: =F24+D25-E25 -> 1260
A26: 23 | B26: 43048 | C26: Twiser two Piece | E26: 60 | F26: =F25+D26-E26 -> 1200
A27: 24 | B27: 43048 | C27: Elfi One piece | E27: 20 | F27: =F26+D27-E27 -> 1180
A28: 25 | B28: 43048 | C28: Niddle screw driver two piece | E28: 40 | F28: =F27+D28-E28 -> 1140
A29: 26 | B29: 43048 | C29: Feedo folder MH | E29: 500 | F29: =F28+D29-E29 -> 640
A30: 27 | B30: 43048 | C30: Niddle screw Boot screw Niddle plate screw 12+12+12 | E30: 72 | F30: =F29+D30-E30 -> 568
A31: 28 | B31: 43048 | C31: Niddle T v 5 19 no 1 Patta | E31: 130 | F31: =F30+D31-E31 -> 438
A32: 29 | B32: 43048 | C32: Cleeper 6piece | E32: 150 | F32: =F31+D32-E32 -> 288
A33: 30 | B33: 43048 | C33: Feedo looper pipe | E33: 20 | F33: =F32+D33-E33 -> 268
... A42: 39 | B42: 43049 | C42: Feedo machine Niddle bar screw | E42: 15 | F42: =F41+D42-E42 -> -3141
A43: 40 | B43: 43050 | C43: Kazmi Sent Farhan Account | D43: 35000 | F43: =F42+D43-E43 -> 31859
A44: 41 | B44: 43050 | C44: Tea for all day | E44: 240 | F44: =F43+D44-E44 -> 31619
A45: 42 | B45: 43050 | C45: Cold drink 500 ML | E45: 50 | F45: =F44+D45-E45 -> 31569
A46: 43 | B46: 43050 | C46: Lunch | E46: 220 | F46: =F45+D46-E46 -> 31349
A47: 44 | B47: 43050 | C47: stationary | E47: 155 | F47: =F46+D47-E47 -> 31194
A48: 45 | B48: 43050 | C48: Gagan contector advance | E48: 8000 | F48: =F47+D48-E48 -> 23194
A49: 46 | B49: 43080 | C49: Factory rent for the month of November 2017 | E49: 21000 | F49: =F48+D49-E49 -> 2194
A50: 47 | B50: 43080 | C50: Gagan contector advance | E50: 4000 | F50: =F49+D50-E50 -> -1806
...
